Traceback (most recent call last):
  File "/Users/user/.rye/py/cpython@3.10.16/lib/python3.10/runpy.py", line 196, in _run_module_as_main
    return _run_code(code, main_globals, None,
  File "/Users/user/.rye/py/cpython@3.10.16/lib/python3.10/runpy.py", line 86, in _run_code
    exec(code, run_globals)
  File "/Users/user/.rye/py/cpython@3.10.16/lib/python3.10/http/server.py", line 1307, in <module>
    test(
  File "/Users/user/.rye/py/cpython@3.10.16/lib/python3.10/http/server.py", line 1258, in test
    with ServerClass(addr, HandlerClass) as httpd:
  File "/Users/user/.rye/py/cpython@3.10.16/lib/python3.10/socketserver.py", line 452, in __init__
    self.server_bind()
  File "/Users/user/.rye/py/cpython@3.10.16/lib/python3.10/http/server.py", line 1301, in server_bind
    return super().server_bind()
  File "/Users/user/.rye/py/cpython@3.10.16/lib/python3.10/http/server.py", line 137, in server_bind
    socketserver.TCPServer.server_bind(self)
  File "/Users/user/.rye/py/cpython@3.10.16/lib/python3.10/socketserver.py", line 466, in server_bind
    self.socket.bind(self.server_address)
OSError: [Errno 48] Address already in use
